Workbook

Sheet Car Listings
A1: Listing ID | B1: Brand | C1: Car Name | D1: Model | E1: Variant | F1: Manufacturing Year | G1: Registration Year | H1: New or Used | I1: Vehicle Type | J1: Fuel Type | K1: Transmission | L1: Number of Owners | M1: Selling Price (INR) | N1: Original Ex-Showroom Price (INR) | O1: Negotiable | P1: Minimum Expected Price (INR) | Q1: Down Payment (INR) | R1: Loan Amount (INR) | S1: Interest Rate (% per annum) | T1: EMI Tenure (Months) | U1: Estimated Monthly EMI (INR) | V1: Loan Eligible | W1: Engine Capacity (cc) | X1: Maximum Power (bhp) | Y1: Mileage (km/l) | Z1: Range (km per charge for EVs) | AA1: Battery Capacity (kWh, for EVs) | AB1: Seating Capacity | AC1: Number of Doors | AD1: Boot Space (litres) | AE1: Safety Rating | AF1: Airbags | AG1: ABS | AH1: Rear Camera | AI1: Parking Sensors | AJ1: Exterior Colour | AK1: Vehicle Condition | AL1: Odometer Reading (km) | AM1: Insurance Valid Until | AN1: Registration State | AO1: City | AP1: Availability Status | AQ1: Listing Date | AR1: Seller Type | AS1: Service History Available | AT1: Warranty Available | AU1: Accident History Disclosed | AV1: Key Features | AW1: Description | AX1: Suitable Buyer | AY1: Estimated Annual Maintenance Cost (INR) | AZ1: Source Type | BA1: Source URL
A2: CAR-1001 | B2: Maruti Suzuki | C2: Maruti Suzuki Swift | D2: Swift | E2: ZXi+ 1.2L DualJet | F2: 2018 | G2: 2019 | H2: Used | I2: Hatchback | J2: Petrol | K2: Manual | L2: 3 | M2: 295000 | N2: 720000 | O2: No | P2: 295000 | Q2: 75000 | R2: =IF(V2="No",0,MAX(0,M2-Q2)) -> 220000 | S2: 11.45 | T2: 36 | U2: =IF(OR(R2<=0,S2<0,T2<=0),"",IF(S2=0,R2/T2,-PMT(S2/1200,T2,R2))) -> 7249 | V2: Yes | W2: 1197 | X2: 89 | Y2: 22.38 | AB2: 5 | AC2: 5 | AD2: 268 | AF2: 6 | AG2: Yes | AH2: Yes | AI2: Yes | AJ2: Pearl Arctic White | AK2: Fair | AL2: 95500 | AM2: 2027-01-01 | AN2: Tamil Nadu | AO2: Chennai | AP2: Available | AQ2: 2026-10-01 | AR2: Individual | AS2: No | AT2: No | AU2: Unknown | AV2: SmartPlay Pro+ 9-inch Touchscreen, Cruise Control, LED Projector Headlamps, Auto AC | AW2: Well-maintained 2018 fair condition Maruti Suzuki Swift ZXi+ 1.2L DualJet (Manual) in Chennai. Powered by a 1197 cc petrol engine delivering 22.38 km/l. Inspected for mechanical reliability. | AX2: Daily Commuter | AY2: 8600 | AZ2: Synthetic Sample
A3: CAR-1002 | B3: Maruti Suzuki | C3: Maruti Suzuki Baleno | D3: Baleno | E3: Alpha 1.2L AGS | F3: 2025 | G3: 2025 | H3: Used | I3: Hatchback | J3: Petrol | K3: AMT | L3: 1 | M3: 875000 | N3: 965000 | O3: Yes | P3: 830000 | Q3: 220000 | R3: =IF(V3="No",0,MAX(0,M3-Q3)) -> 655000 | S3: 10.4 | T3: 48 | U3: =IF(OR(R3<=0,S3<0,T3<=0),"",IF(S3=0,R3/T3,-PMT(S3/1200,T3,R3))) -> 16739 | V3: Yes | W3: 1197 | X3: 89 | Y3: 22.94 | AB3: 5 | AC3: 5 | AD3: 318 | AE3: 4 Star (Bharat NCAP) | AF3: 6 | AG3: Yes | AH3: Yes | AI3: Yes | AJ3: Titan Grey | AK3: Like New | AL3: 10200 | AM3: 2026-12-06 | AN3: Karnataka | AO3: Bengaluru | AP3: Available | AQ3: 2026-09-04 | AR3: Dealer | AS3: Yes | AT3: Yes | AU3: No | AV3: Head-Up Display, 360 View Camera, 9-inch SmartPlay Pro+, UV Cut Glass | AW3: Well-maintained 2025 like new condition Maruti Suzuki Baleno Alpha 1.2L AGS (AMT) in Bengaluru. Powered by a 1197 cc petrol engine delivering 22.94 km/l. Complete service history available. | AX3: Family | AY3: 7100 | AZ3: Synthetic Sample
A4: CAR-1003 | B4: Maruti Suzuki | C4: Maruti Suzuki Brezza | D4: Brezza | E4: ZXi+ 1.5L Smart Hybrid AT | F4: 2020 | G4: 2020 | H4: Used | I4: SUV | J4: Petrol | K4: Automatic | L4: 1 | M4: 655000 | N4: 1190000 | O4: Yes | P4: 630000 | Q4: 165000 | R4: =IF(V4="No",0,MAX(0,M4-Q4)) -> 490000 | S4: 11.15 | T4: 60 | U4: =IF(OR(R4<=0,S4<0,T4<=0),"",IF(S4=0,R4/T4,-PMT(S4/1200,T4,R4))) -> 10690 | V4: Yes | W4: 1462 | X4: 102 | Y4: 19.8 | AB4: 5 | AC4: 5 | AD4: 328 | AE4: 4 Star (Global NCAP) | AF4: 6 | AG4: Yes | AH4: Yes | AI4: Yes | AJ4: Abyss Black | AK4: Excellent | AL4: 54300 | AM4: 2027-03-11 | AN4: Telangana | AO4: Hyderabad | AP4: Available | AQ4: 2026-10-07 | AR4: Dealer | AS4: Yes | AT4: No | AU4: No | AV4: Electric Sunroof, Paddle Shifters, 360 Degree Camera, Wireless Charging | AW4: Well-maintained 2020 excellent condition Maruti Suzuki Brezza ZXi+ 1.5L Smart Hybrid AT (Automatic) in Hyderabad. Powered by a 1462 cc petrol engine delivering 19.8 km/l. Complete service history available. | AX4: Family | AY4: 10200 | AZ4: Synthetic Sample
A5: CAR-1004 | B5: Maruti Suzuki | C5: Maruti Suzuki Wagon R | D5: Wagon R | E5: VXi 1.0L S-CNG | F5: 2015 | G5: 2015 | H5: Used | I5: Hatchback | J5: CNG | K5: Manual | L5: 2 | M5: 150000 | N5: 500000 | O5: No | P5: 150000 | Q5: 40000 | R5: =IF(V5="No",0,MAX(0,M5-Q5)) -> 0 | S5: 0 | T5: 0 | U5: =IF(OR(R5<=0,S5<0,T5<=0),"",IF(S5=0,R5/T5,-PMT(S5/1200,T5,R5))) | V5: No | W5: 998 | X5: 56 | Y5: 33.47 | AB5: 5 | AC5: 5 | AD5: 341 | AF5: 2 | AG5: Yes | AH5: No | AI5: Yes | AJ5: Starry Night Blue | AK5: Fair | AL5: 139700 | AM5: 2026-12-16 | AN5: Maharashtra | AO5: Mumbai | AP5: Available | AQ5: 2026-09-10 | AR5: Individual | AS5: Yes | AT5: No | AU5: No | AV5: Factory Fitted S-CNG Dual Interdependent ECUs, Keyless Entry, Power Windows | AW5: Well-maintained 2015 fair condition Maruti Suzuki Wagon R VXi 1.0L S-CNG (Manual) in Mumbai. Powered by a 998 cc cng engine delivering 33.47 km/l. Complete service history available. | AX5: First-Time Buyer | AY5: 7900 | AZ5: Synthetic Sample
A6: CAR-1005 | B6: Maruti Suzuki | C6: Maruti Suzuki Ertiga | D6: Ertiga | E6: ZXi 1.5L S-CNG | F6: 2022 | G6: 2022 | H6: Used | I6: MUV | J6: CNG | K6: Manual | L6: 1 | M6: 720000 | N6: 1070000 | O6: Yes | P6: 685000 | Q6: 180000 | R6: =IF(V6="No",0,MAX(0,M6-Q6)) -> 540000 | S6: 10.85 | T6: 48 | U6: =IF(OR(R6<=0,S6<0,T6<=0),"",IF(S6=0,R6/T6,-PMT(S6/1200,T6,R6))) -> 13917 | V6: Yes | W6: 1462 | X6: 87 | Y6: 26.11 | AB6: 7 | AC6: 5 | AD6: 209 | AF6: 4 | AG6: Yes | AH6: Yes | AI6: Yes | AJ6: Pearl Arctic White | AK6: Excellent | AL6: 56700 | AM6: 2027-05-21 | AN6: Delhi | AO6: Delhi | AP6: Reserved | AQ6: 2026-10-13 | AR6: Dealer | AS6: Yes | AT6: Yes | AU6: No | AV6: 7-Seater Reclining Rows, Roof Mounted AC Vents, 7-inch SmartPlay Studio | AW6: Well-maintained 2022 excellent condition Maruti Suzuki Ertiga ZXi 1.5L S-CNG (Manual) in Delhi. Powered by a 1462 cc cng engine delivering 26.11 km/l. Complete service history available. | AX6: Family | AY6: 9000 | AZ6: Synthetic Sample
A7: CAR-1006 | B7: Maruti Suzuki | C7: Maruti Suzuki Grand Vitara | D7: Grand Vitara | E7: Alpha+ 1.5L Intelligent Electric Hybrid | F7: 2024 | G7: 2025 | H7: Used | I7: SUV | J7: Hybrid | K7: CVT | L7: 1 | M7: 1555000 | N7: 1900000 | O7: Yes | P7: 1495000 | Q7: 390000 | R7: =IF(V7="No",0,MAX(0,M7-Q7)) -> 1165000 | S7: 10.55 | T7: 60 | U7: =IF(OR(R7<=0,S7<0,T7<=0),"",IF(S7=0,R7/T7,-PMT(S7/1200,T7,R7))) -> 25069 | V7: Yes | W7: 1490 | X7: 114 | Y7: 27.97 | AB7: 5 | AC7: 5 | AD7: 265 | AE7: 5 Star (Bharat NCAP) | AF7: 6 | AG7: Yes | AH7: Yes | AI7: Yes | AJ7: Titan Grey | AK7: Like New | AL7: 23200 | AM7: 2026-12-26 | AN7: Maharashtra | AO7: Pune | AP7: Sold | AQ7: 2026-09-16 | AR7: Dealer | AS7: Yes | AT7: Yes | AU7: No | AV7: Panoramic Sunroof, Ventilated Front Seats, Strong Hybrid e-CVT, TPMS | AW7: Well-maintained 2024 like new condition Maruti Suzuki Grand Vitara Alpha+ 1.5L Intelligent Electric Hybrid (CVT) in Pune. Powered by a 1490 cc hybrid engine delivering 27.97 km/l. Complete service history available. | AX7: Family | AY7: 9900 | AZ7: Synthetic Sample
A8: CAR-1007 | B8: Maruti Suzuki | C8: Maruti Suzuki Dzire | D8: Dzire | E8: ZXi+ 1.2L AGS | F8: 2024 | G8: 2024 | H8: Used | I8: Sedan | J8: Petrol | K8: AMT | L8: 1 | M8: 790000 | N8: 965000 | O8: No | P8: 790000 | Q8: 200000 | R8: =IF(V8="No",0,MAX(0,M8-Q8)) -> 590000 | S8: 10.55 | T8: 36 | U8: =IF(OR(R8<=0,S8<0,T8<=0),"",IF(S8=0,R8/T8,-PMT(S8/1200,T8,R8))) -> 19190 | V8: Yes | W8: 1197 | X8: 80 | Y8: 25.71 | AB8: 5 | AC8: 4 | AD8: 382 | AE8: 5 Star (Global NCAP) | AF8: 6 | AG8: Yes | AH8: Yes | AI8: Yes | AJ8: Abyss Black | AK8: Like New | AL8: 21500 | AM8: 2027-07-04 | AN8: Tamil Nadu | AO8: Coimbatore | AP8: Available | AQ8: 2026-10-19 | AR8: Individual | AS8: Yes | AT8: Yes | AU8: No | AV8: Electric Sunroof, 360 HD View Camera, Wireless Android Auto & CarPlay | AW8: Well-maintained 2024 like new condition Maruti Suzuki Dzire ZXi+ 1.2L AGS (AMT) in Coimbatore. Powered by a 1197 cc petrol engine delivering 25.71 km/l. Complete service history available. | AX8: Family | AY8: 7100 | AZ8: Synthetic Sample
A9: CAR-1008 | B9: Hyundai | C9: Hyundai Creta | D9: Creta | E9: SX (O) 1.5L Turbo GDi DCT | F9: 2019 | G9: 2019 | H9: Used | I9: SUV | J9: Petrol | K9: DCT | L9: 1 | M9: 825000 | N9: 1660000 | O9: Yes | P9: 785000 | Q9: 205000 | R9: =IF(V9="No",0,MAX(0,M9-Q9)) -> 620000 | S9: 11.3 | T9: 48 | U9: =IF(OR(R9<=0,S9<0,T9<=0),"",IF(S9=0,R9/T9,-PMT(S9/1200,T9,R9))) -> 16115 | V9: Yes | W9: 1482 | X9: 158 | Y9: 18.4 | AB9: 5 | AC9: 5 | AD9: 433 | AF9: 6 | AG9: Yes | AH9: Yes | AI9: Yes | AJ9: Starry Night Blue | AK9: Good | AL9: 68500 | AM9: 2026-12-09 | AN9: Kerala | AO9: Kochi | AP9: Available | AQ9: 2026-09-22 | AR9: Dealer | AS9: No | AT9: No | AU9: No | AV9: Level 2 ADAS, Bose 8-Speaker Audio, Panoramic Sunroof, Dual 10.25-inch Displays | AW9: Well-maintained 2019 good condition Hyundai Creta SX (O) 1.5L Turbo GDi DCT (DCT) in Kochi. Powered by a 1482 cc petrol engine delivering 18.4 km/l. Inspected for mechanical reliability. | AX9: Family | AY9: 12500 | AZ9: Synthetic Sample
A10: CAR-1009 | B10: Hyundai | C10: Hyundai Creta | D10: Creta | E10: SX Tech 1.5L CRDi AT | F10: 2026 | G10: 2026 | H10: New | I10: SUV | J10: Diesel | K10: Automatic | L10: 0 | M10: 1910000 | N10: 1910000 | O10: Yes | P10: 1835000 | Q10: 380000 | R10: =IF(V10="No",0,MAX(0,M10-Q10)) -> 1530000 | S10: 8.95 | T10: 84 | U10: =IF(OR(R10<=0,S10<0,T10<=0),"",IF(S10=0,R10/T10,-PMT(S10/1200,T10,R10))) -> 24577 | V10: Yes | W10: 1493 | X10: 114 | Y10: 19.1 | AB10: 5 | AC10: 5 | AD10: 433 | AF10: 6 | AG10: Yes | AH10: Yes | AI10: Yes | AJ10: Pearl Arctic White | AK10: New | AL10: 23 | AM10: 2029-09-14 | AN10: Gujarat | AO10: Ahmedabad | AP10: Available | AQ10: 2026-10-03 | AR10: Dealer | AS10: Yes | AT10: Yes | AU10: No | AV10: Panoramic Sunroof, Voice Enabled Smart Controls, Bose Sound, Bluelink Connected Car | AW10: Brand-new 2026 showroom condition Hyundai Creta SX Tech 1.5L CRDi AT (Automatic) in Ahmedabad. Powered by a 1493 cc diesel engine delivering 19.1 km/l. Complete service history available. | AX10: Family | AY10: 10500 | AZ10: Synthetic Sample
A11: CAR-1010 | B11: Hyundai | C11: Hyundai i20 | D11: i20 | E11: Asta (O) 1.2L Kappa IVT | F11: 2021 | G11: 2021 | H11: Used | I11: Hatchback | J11: Petrol | K11: CVT | L11: 2 | M11: 595000 | N11: 980000 | O11: No | P11: 595000 | Q11: 150000 | R11: =IF(V11="No",0,MAX(0,M11-Q11)) -> 445000 | S11: 11 | T11: 36 | U11: =IF(OR(R11<=0,S11<0,T11<=0),"",IF(S11=0,R11/T11,-PMT(S11/1200,T11,R11))) -> 14569 | V11: Yes | W11: 1197 | X11: 87 | Y11: 19.65 | AB11: 5 | AC11: 5 | AD11: 311 | AE11: 3 Star (Global NCAP) | AF11: 6 | AG11: Yes | AH11: Yes | AI11: Yes | AJ11: Titan Grey | AK11: Excellent | AL11: 50200 | AM11: 2026-12-19 | AN11: West Bengal | AO11: Kolkata | AP11: Available | AQ11: 2026-09-06 | AR11: Individual | AS11: Yes | AT11: No | AU11: No | AV11: Electric Sunroof, Bose 7-Speaker System, 10.25-inch HD Infotainment, Ambient Lighting | AW11: Well-maintained 2021 excellent condition Hyundai i20 Asta (O) 1.2L Kappa IVT (CVT) in Kolkata. Powered by a 1197 cc petrol engine delivering 19.65 km/l. Complete service history available. | AX11: Daily Commuter | AY11: 8900 | AZ11: Synthetic Sample
A12: CAR-1011 | B12: Hyundai | C12: Hyundai Verna | D12: Verna | E12: SX (O) 1.5L Turbo GDi DCT | F12: 2016 | G12: 2017 | H12: Used | I12: Sedan | J12: Petrol | K12: DCT | L12: 2 | M12: 480000 | N12: 1305000 | O12: Yes | P12: 455000 | Q12: 120000 | R12: =IF(V12="No",0,MAX(0,M12-Q12)) -> 360000 | S12: 11.75 | T12: 48 | U12: =IF(OR(R12<=0,S12<0,T12<=0),"",IF(S12=0,R12/T12,-PMT(S12/1200,T12,R12))) -> 9436 | V12: Yes | W12: 1482 | X12: 158 | Y12: 20.6 | AB12: 5 | AC12: 4 | AD12: 528 | AE12: 5 Star (Global NCAP) | AF12: 6 | AG12: Yes | AH12: Yes | AI12: Yes | AJ12: Abyss Black | AK12: Good | AL12: 76700 | AM12: 2027-11-24 | AN12: Tamil Nadu | AO12: Chennai | AP12: Reserved | AQ12: 2026-10-09 | AR12: Dealer | AS12: Yes | AT12: No | AU12: No | AV12: Hyundai SmartSense Level 2 ADAS, Heated & Ventilated Front Seats, Horizon LED Lamp | AW12: Well-maintained 2016 good condition Hyundai Verna SX (O) 1.5L Turbo GDi DCT (DCT) in Chennai. Powered by a 1482 cc petrol engine delivering 20.6 km/l. Complete service history available. | AX12: Enthusiast | AY12: 12700 | AZ12: Synthetic Sample
A13: CAR-1012 | B13: Hyundai | C13: Hyundai Venue | D13: Venue | E13: SX (O) 1.0L Turbo DCT | F13: 2023 | G13: 2023 | H13: Used | I13: SUV | J13: Petrol | K13: DCT | L13: 1 | M13: 925000 | N13: 1245000 | O13: Yes | P13: 890000 | Q13: 230000 | R13: =IF(V13="No",0,MAX(0,M13-Q13)) -> 695000 | S13: 10.7 | T13: 60 | U13: =IF(OR(R13<=0,S13<0,T13<=0),"",IF(S13=0,R13/T13,-PMT(S13/1200,T13,R13))) -> 15007 | V13: Yes | W13: 998 | X13: 118 | Y13: 18.31 | AB13: 5 | AC13: 5 | AD13: 350 | AF13: 6 | AG13: Yes | AH13: Yes | AI13: Yes | AJ13: Starry Night Blue | AK13: Excellent | AL13: 28800 | AM13: 2026-12-02 | AN13: Karnataka | AO13: Bengaluru | AP13: Sold | AQ13: 2026-09-12 | AR13: Dealer | AS13: Yes | AT13: Yes | AU13: No | AV13: Smart Electric Sunroof, 4-Way Power Driver Seat, Air Purifier, Dashcam | AW13: Well-maintained 2023 excellent condition Hyundai Venue SX (O) 1.0L Turbo DCT (DCT) in Bengaluru. Powered by a 998 cc petrol engine delivering 18.31 km/l. Complete service history available. | AX13: Daily Commuter | AY13: 9000 | AZ13: Synthetic Sample
A14: CAR-1013 | B14: Hyundai | C14: Hyundai Ioniq 5 | D14: Ioniq 5 | E14: RWD 72.6 kWh Long Range | F14: 2023 | G14: 2023 | H14: Used | I14: SUV | J14: Electric | K14: Automatic | L14: 1 | M14: 3160000 | N14: 4260000 | O14: No | P14: 3160000 | Q14: 790000 | R14: =IF(V14="No",0,MAX(0,M14-Q14)) -> 2370000 | S14: 10.7 | T14: 36 | U14: =IF(OR(R14<=0,S14<0,T14<=0),"",IF(S14=0,R14/T14,-PMT(S14/1200,T14,R14))) -> 77254 | V14: Yes | X14: 215 | Z14: 631 | AA14: 72.6 | AB14: 5 | AC14: 5 | AD14: 527 | AE14: 5 Star (Euro NCAP) | AF14: 6 | AG14: Yes | AH14: Yes | AI14: Yes | AJ14: Pearl Arctic White | AK14: Like New | AL14: 26900 | AM14: 2027-01-07 | AN14: Telangana | AO14: Hyderabad | AP14: Available | AQ14: 2026-10-15 | AR14: Individual | AS14: Yes | AT14: Yes | AU14: No | AV14: 800V Ultra-Fast Charging, Vehicle-to-Load (V2L), Parametric Pixel LED, Level 2 ADAS | AW14: Well-maintained 2023 like new condition Hyundai Ioniq 5 RWD 72.6 kWh Long Range (Automatic) in Hyderabad. Powered by a 72.6 kWh battery delivering 631 km certified range. Complete service history available. | AX14: Enthusiast | AY14: 6900 | AZ14: Synthetic Sample
A15: CAR-1014 | B15: Hyundai | C15: Hyundai Grand i10 Nios | D15: Grand i10 Nios | E15: Sportz 1.2L Hy-CNG Duo | F15: 2025 | G15: 2025 | H15: Used | I15: Hatchback | J15: CNG | K15: Manual | L15: 1 | M15: 735000 | N15: 810000 | O15: Yes | P15: 700000 | Q15: 185000 | R15: =IF(V15="No",0,MAX(0,M15-Q15)) -> 550000 | S15: 10.4 | T15: 48 | U15: =IF(OR(R15<=0,S15<0,T15<=0),"",IF(S15=0,R15/T15,-PMT(S15/1200,T15,R15))) -> 14055 | V15: Yes | W15: 1197 | X15: 68 | Y15: 27.3 | AB15: 5 | AC15: 5 | AD15: 240 | AF15: 6 | AG15: Yes | AH15: Yes | AI15: Yes | AJ15: Titan Grey | AK15: Like New | AL15: 12400 | AM15: 2026-12-12 | AN15: Maharashtra | AO15: Mumbai | AP15: Available | AQ15: 2026-09-18 | AR15: Dealer | AS15: Yes | AT15: Yes | AU15: No | AV15: Dual Cylinder CNG with Usable Boot, 8-inch Touchscreen, Rear AC Vents | AW15: Well-maintained 2025 like new condition Hyundai Grand i10 Nios Sportz 1.2L Hy-CNG Duo (Manual) in Mumbai. Powered by a 1197 cc cng engine delivering 27.3 km/l. Complete service history available. | AX15: First-Time Buyer | AY15: 6400 | AZ15: Synthetic Sample
A16: CAR-1015 | B16: Tata | C16: Tata Nexon | D16: Nexon | E16: Fearless+ S 1.2L Turbo DCA | F16: 2020 | G16: 2020 | H16: Used | I16: SUV | J16: Petrol | K16: DCT | L16: 1 | M16: 690000 | N16: 1260000 | O16: Yes | P16: 660000 | Q16: 175000 | R16: =IF(V16="No",0,MAX(0,M16-Q16)) -> 515000 | S16: 11.15 | T16: 60 | U16: =IF(OR(R16<=0,S16<0,T16<=0),"",IF(S16=0,R16/T16,-PMT(S16/1200,T16,R16))) -> 11236 | V16: Yes | W16: 1199 | X16: 118 | Y16: 17.01 | AB16: 5 | AC16: 5 | AD16: 382 | AE16: 5 Star (Global & Bharat NCAP) | AF16: 6 | AG16: Yes | AH16: Yes | AI16: Yes | AJ16: Abyss Black | AK16: Excellent | AL16: 60500 | AM16: 2027-03-17 | AN16: Delhi | AO16: Delhi | AP16: Available | AQ16: 2026-10-21 | AR16: Dealer | AS16: No | AT16: No | AU16: No | AV16: 10.25-inch Harman Floating Infotainment, 360 Surround View, Ventilated Seats, JBL Audio | AW16: Well-maintained 2020 excellent condition Tata Nexon Fearless+ S 1.2L Turbo DCA (DCT) in Delhi. Powered by a 1199 cc petrol engine delivering 17.01 km/l. Inspected for mechanical reliability. | AX16: Family | AY16: 10500 | AZ16: Synthetic Sample
A17: CAR-1016 | B17: Tata | C17: Tata Nexon.ev | D17: Nexon.ev | E17: Empowered+ 45 kWh Long Range | F17: 2024 | G17: 2025 | H17: Used | I17: SUV | J17: Electric | K17: Automatic | L17: 1 | M17: 1325000 | N17: 1615000 | O17: No | P17: 1325000 | Q17: 330000 | R17: =IF(V17="No",0,MAX(0,M17-Q17)) -> 995000 | S17: 10.55 | T17: 36 | U17: =IF(OR(R17<=0,S17<0,T17<=0),"",IF(S17=0,R17/T17,-PMT(S17/1200,T17,R17))) -> 32363 | V17: Yes | X17: 142 | Z17: 489 | AA17: 45 | AB17: 5 | AC17: 5 | AD17: 350 | AE17: 5 Star (Bharat NCAP) | AF17: 6 | AG17: Yes | AH17: Yes | AI17: Yes | AJ17: Starry Night Blue | AK17: Like New | AL17: 18300 | AM17: 2026-12-22 | AN17: Maharashtra | AO17: Pune | AP17: Available | AQ17: 2026-09-02 | AR17: Individual | AS17: Yes | AT17: Yes | AU17: Unknown | AV17: Panoramic Sunroof, V2V & V2L Charging, 12.3-inch Cinematic Screen, Arcade.ev App Suite | AW17: Well-maintained 2024 like new condition Tata Nexon.ev Empowered+ 45 kWh Long Range (Automatic) in Pune. Powered by a 45 kWh battery delivering 489 km certified range. Complete service history available. | AX17: Daily Commuter | AY17: 5200 | AZ17: Synthetic Sample
A18: CAR-1017 | B18: Tata | C18: Tata Punch | D18: Punch | E18: Accomplished+ S iCNG | F18: 2022 | G18: 2022 | H18: Used | I18: SUV | J18: CNG | K18: Manual | L18: 1 | M18: 595000 | N18: 885000 | O18: Yes | P18: 565000 | Q18: 150000 | R18: =IF(V18="No",0,MAX(0,M18-Q18)) -> 445000 | S18: 10.85 | T18: 48 | U18: =IF(OR(R18<=0,S18<0,T18<=0),"",IF(S18=0,R18/T18,-PMT(S18/1200,T18,R18))) -> 11469 | V18: Yes | W18: 1199 | X18: 72 | Y18: 26.99 | AB18: 5 | AC18: 5 | AD18: 210 | AE18: 5 Star (Global NCAP) | AF18: 2 | AG18: Yes | AH18: Yes | AI18: Yes | AJ18: Pearl Arctic White | AK18: Excellent | AL18: 60900 | AM18: 2027-05-27 | AN18: Tamil Nadu | AO18: Coimbatore | AP18: Reserved | AQ18: 2026-10-05 | AR18: Dealer | AS18: Yes | AT18: Yes | AU18: No | AV18: Twin-Cylinder iCNG Technology, Voice Assisted Electric Sunroof, 7-inch Harman Screen | AW18: Well-maintained 2022 excellent condition Tata Punch Accomplished+ S iCNG (Manual) in Coimbatore. Powered by a 1199 cc cng engine delivering 26.99 km/l. Complete service history available. | AX18: First-Time Buyer | AY18: 7400 | AZ18: Synthetic Sample
A19: CAR-1018 | B19: Tata | C19: Tata Punch.ev | D19: Punch.ev | E19: Empowered+ S 35 kWh Long Range | F19: 2024 | G19: 2024 | H19: Used | I19: SUV | J19: Electric | K19: Automatic | L19: 1 | M19: 1125000 | N19: 1375000 | O19: Yes | P19: 1080000 | Q19: 280000 | R19: =IF(V19="No",0,MAX(0,M19-Q19)) -> 845000 | S19: 10.55 | T19: 60 | U19: =IF(OR(R19<=0,S19<0,T19<=0),"",IF(S19=0,R19/T19,-PMT(S19/1200,T19,R19))) -> 18183 | V19: Yes | X19: 120 | Z19: 421 | AA19: 35 | AB19: 5 | AC19: 5 | AD19: 366 | AE19: 5 Star (Bharat NCAP) | AF19: 6 | AG19: Yes | AH19: Yes | AI19: Yes | AJ19: Titan Grey | AK19: Like New | AL19: 18100 | AM19: 2026-12-05 | AN19: Kerala | AO19: Kochi | AP19: Sold | AQ19: 2026-09-08 | AR19: Dealer | AS19: Yes | AT19: Yes | AU19: No | AV19: acti.ev Pure EV Architecture, Frunk Storage, 360 Camera, Electronic Parking Brake | AW19: Well-maintained 2024 like new condition Tata Punch.ev Empowered+ S 35 kWh Long Range (Automatic) in Kochi. Powered by a 35 kWh battery delivering 421 km certified range. Complete service history available. | AX19: Daily Commuter | AY19: 4900 | AZ19: Synthetic Sample
A20: CAR-1019 | B20: Tata | C20: Tata Harrier | D20: Harrier | E20: Fearless+ Dark 2.0L Kryotec AT | F20: 2024 | G20: 2024 | H20: Used | I20: SUV | J20: Diesel | K20: Automatic | L20: 1 | M20: 2045000 | N20: 2495000 | O20: No | P20: 2045000 | Q20: 510000 | R20: =IF(V20="No",0,MAX(0,M20-Q20)) -> 1535000 | S20: 10.55 | T20: 36 | U20: =IF(OR(R20<=0,S20<0,T20<=0),"",IF(S20=0,R20/T20,-PMT(S20/1200,T20,R20))) -> 49927 | V20: Yes | W20: 1956 | X20: 168 | Y20: 16.8 | AB20: 5 | AC20: 5 | AD20: 445 | AE20: 5 Star (Global & Bharat NCAP) | AF20: 7 | AG20: Yes | AH20: Yes | AI20: Yes | AJ20: Abyss Black | AK20: Like New | AL20: 21500 | AM20: 2027-07-10 | AN20: Gujarat | AO20: Ahmedabad | AP20: Available | AQ20: 2026-10-11 | AR20: Individual | AS20: Yes | AT20: Yes | AU20: No | AV20: ADAS Level 2, Gesture Controlled Powered Tailgate, Dual-Zone Climate Control, Panoramic Sunroof | AW20: Well-maintained 2024 like new condition Tata Harrier Fearless+ Dark 2.0L Kryotec AT (Automatic) in Ahmedabad. Powered by a 1956 cc diesel engine delivering 16.8 km/l. Complete service history available. | AX20: Family | AY20: 13500 | AZ20: Synthetic Sample
A21: CAR-1020 | B21: Tata | C21: Tata Safari | D21: Safari | E21: Accomplished+ 2.0L Kryotec AT 6S | F21: 2019 | G21: 2019 | H21: Used | I21: SUV | J21: Diesel | K21: Automatic | L21: 1 | M21: 1020000 | N21: 2255000 | O21: Yes | P21: 970000 | Q21: 255000 | R21: =IF(V21="No",0,MAX(0,M21-Q21)) -> 765000 | S21: 11.3 | T21: 48 | U21: =IF(OR(R21<=0,S21<0,T21<=0),"",IF(S21=0,R21/T21,-PMT(S21/1200,T21,R21))) -> 19883 | V21: Yes | W21: 1956 | X21: 168 | Y21: 16.3 | AB21: 6 | AC21: 5 | AD21: 420 | AE21: 5 Star (Global & Bharat NCAP) | AF21: 7 | AG21: Yes | AH21: Yes | AI21: Yes | AJ21: Starry Night Blue | AK21: Fair | AL21: 112400 | AM21: 2026-12-15 | AN21: West Bengal | AO21: Kolkata | AP21: Available | AQ21: 2026-09-14 | AR21: Dealer | AS21: Yes | AT21: No | AU21: No | AV21: 2nd Row Ventilated Captain Seats, Boss Mode, 10-Speaker JBL Dolby Atmos, Panoramic Sunroof | AW21: Well-maintained 2019 fair condition Tata Safari Accomplished+ 2.0L Kryotec AT 6S (Automatic) in Kolkata. Powered by a 1956 cc diesel engine delivering 16.3 km/l. Complete service history available. | AX21: Family | AY21: 16900 | AZ21: Synthetic Sample
A22: CAR-1021 | B22: Tata | C22: Tata Curvv.ev | D22: Curvv.ev | E22: Empowered+ A 55 kWh | F22: 2023 | G22: 2024 | H22: Used | I22: Coupe | J22: Electric | K22: Automatic | L22: 1 | M22: 1510000 | N22: 2035000 | O22: Yes | P22: 1450000 | Q22: 380000 | R22: =IF(V22="No",0,MAX(0,M22-Q22)) -> 1130000 | S22: 10.7 | T22: 60 | U22: =IF(OR(R22<=0,S22<0,T22<=0),"",IF(S22=0,R22/T22,-PMT(S22/1200,T22,R22))) -> 24400 | V22: Yes | X22: 165 | Z22: 585 | AA22: 55 | AB22: 5 | AC22: 5 | AD22: 500 | AE22: 5 Star (Bharat NCAP) | AF22: 6 | AG22: Yes | AH22: Yes | AI22: Yes | AJ22: Pearl Arctic White | AK22: Like New | AL22: 23800 | AM22: 2027-09-20 | AN22: Tamil Nadu | AO22: Chennai | AP22: Available | AQ22: 2026-10-17 | AR22: Dealer | AS22: Yes | AT22: Yes | AU22: No | AV22: SUV Coupe Design, Level 2 ADAS (20 Features), Acoustic Vehicle Alert System, Powered Tailgate | AW22: Well-maintained 2023 like new condition Tata Curvv.ev Empowered+ A 55 kWh (Automatic) in Chennai. Powered by a 55 kWh battery delivering 585 km certified range. Complete service history available. | AX22: Enthusiast | AY22: 5800 | AZ22: Synthetic Sample
A23: CAR-1022 | B23: Mahindra | C23: Mahindra XUV700 | D23: XUV700 | E23: AX7 Luxury Pack 2.2L mHawk AT AWD | F23: 2021 | G23: 2021 | H23: Used | I23: SUV | J23: Diesel | K23: Automatic | L23: 2 | M23: 1355000 | N23: 2230000 | O23: No | P23: 1355000 | Q23: 340000 | R23: =IF(V23="No",0,MAX(0,M23-Q23)) -> 1015000 | S23: 11 | T23: 36 | U23: =IF(OR(R23<=0,S23<0,T23<=0),"",IF(S23=0,R23/T23,-PMT(S23/1200,T23,R23))) -> 33230 | V23: Yes | W23: 2198 | X23: 182 | Y23: 15.5 | AB23: 7 | AC23: 5 | AD23: 240 | AE23: 5 Star (Global NCAP) | AF23: 7 | AG23: Yes | AH23: Yes | AI23: Yes | AJ23: Titan Grey | AK23: Excellent | AL23: 54500 | AM23: 2026-12-25 | AN23: Karnataka | AO23: Bengaluru | AP23: Available | AQ23: 2026-09-20 | AR23: Individual | AS23: No | AT23: No | AU23: No | AV23: Skyroof Panoramic Sunroof, Adrenox Dual 10.25-inch Screens, Sony 12-Speaker 3D Audio, ADAS | AW23: Well-maintained 2021 excellent condition Mahindra XUV700 AX7 Luxury Pack 2.2L mHawk AT AWD (Automatic) in Bengaluru. Powered by a 2198 cc diesel engine delivering 15.5 km/l. Inspected for mechanical reliability. | AX23: Family | AY23: 15400 | AZ23: Synthetic Sample
A24: CAR-1023 | B24: Mahindra | C24: Mahindra Scorpio-N | D24: Scorpio-N | E24: Z8L 2.2L mHawk 4XPLOR AT | F24: 2016 | G24: 2016 | H24: Used | I24: SUV | J24: Diesel | K24: Automatic | L24: 2 | M24: 615000 | N24: 1840000 | O24: Yes | P24: 585000 | Q24: 155000 | R24: =IF(V24="No",0,MAX(0,M24-Q24)) -> 460000 | S24: 11.75 | T24: 48 | U24: =IF(OR(R24<=0,S24<0,T24<=0),"",IF(S24=0,R24/T24,-PMT(S24/1200,T24,R24))) -> 12057 | V24: Yes | W24: 2198 | X24: 172 | Y24: 15.4 | AB24: 7 | AC24: 5 | AD24: 460 | AE24: 5 Star (Global NCAP) | AF24: 6 | AG24: Yes | AH24: Yes | AI24: Yes | AJ24: Abyss Black | AK24: Fair | AL24: 145000 | AM24: 2027-11-03 | AN24: Telangana | AO24: Hyderabad | AP24: Reserved | AQ24: 2026-10-01 | AR24: Dealer | AS24: Yes | AT24: No | AU24: No | AV24: 4XPLOR Terrain Management, Body-on-Frame 4WD, Sony 3D Audio, Ventilated Seats | AW24: Well-maintained 2016 fair condition Mahindra Scorpio-N Z8L 2.2L mHawk 4XPLOR AT (Automatic) in Hyderabad. Powered by a 2198 cc diesel engine delivering 15.4 km/l. Complete service history available. | AX24: Enthusiast | AY24: 17100 | AZ24: Synthetic Sample
A25: CAR-1024 | B25: Mahindra | C25: Mahindra Thar ROXX | D25: Thar ROXX | E25: AX7L 2.2L mHawk 4WD AT | F25: 2026 | G25: 2026 | H25: New | I25: SUV | J25: Diesel | K25: Automatic | L25: 0 | M25: 2249000 | N25: 2250000 | O25: No | P25: 2249000 | Q25: 450000 | R25: =IF(V25="No",0,MAX(0,M25-Q25)) -> 1799000 | S25: 8.95 | T25: 84 | U25: =IF(OR(R25<=0,S25<0,T25<=0),"",IF(S25=0,R25/T25,-PMT(S25/1200,T25,R25))) -> 28899 | V25: Yes | W25: 2184 | X25: 172 | Y25: 15.2 | AB25: 5 | AC25: 5 | AD25: 447 | AE25: 5 Star (Bharat NCAP) | AF25: 6 | AG25: Yes | AH25: Yes | AI25: Yes | AJ25: Starry Night Blue | AK25: New | AL25: 38 | AM25: 2029-12-08 | AN25: Maharashtra | AO25: Mumbai | AP25: Sold | AQ25: 2026-09-04 | AR25: Dealer | AS25: Yes | AT25: Yes | AU25: No | AV25: 5-Door Off-Roader, CrawlSmart, IntelliTurn, Panoramic Skyroof, Harman Kardon 9-Speaker Audio | AW25: Brand-new 2026 showroom condition Mahindra Thar ROXX AX7L 2.2L mHawk 4WD AT (Automatic) in Mumbai. Powered by a 2184 cc diesel engine delivering 15.2 km/l. Complete service history available. | AX25: Enthusiast | AY25: 11800 | AZ25: Synthetic Sample
A26: CAR-1025 | B26: Mahindra | C26: Mahindra XUV 3XO | D26: XUV 3XO | E26: AX7L 1.2L TGDi AT | F26: 2023 | G26: 2023 | H26: Used | I26: SUV | J26: Petrol | K26: Automatic | L26: 1 | M26: 1065000 | N26: 1435000 | O26: No | P26: 1065000 | Q26: 265000 | R26: =IF(V26="No",0,MAX(0,M26-Q26)) -> 800000 | S26: 10.7 | T26: 36 | U26: =IF(OR(R26<=0,S26<0,T26<=0),"",IF(S26=0,R26/T26,-PMT(S26/1200,T26,R26))) -> 26077 | V26: Yes | W26: 1197 | X26: 129 | Y26: 18.2 | AB26: 5 | AC26: 5 | AD26: 364 | AE26: 5 Star (Bharat NCAP) | AF26: 6 | AG26: Yes | AH26: Yes | AI26: Yes | AJ26: Pearl Arctic White | AK26: Like New | AL26: 23900 | AM26: 2027-01-13 | AN26: Delhi | AO26: Delhi | AP26: Available | AQ26: 2026-10-07 | AR26: Individual | AS26: Yes | AT26: Yes | AU26: No | AV26: Segment-First Skyroof, Level 2 ADAS, Harman Kardon Audio with Amplifier, Dual-Zone AC | AW26: Well-maintained 2023 like new condition Mahindra XUV 3XO AX7L 1.2L TGDi AT (Automatic) in Delhi. Powered by a 1197 cc petrol engine delivering 18.2 km/l. Complete service history available. | AX26: Family | AY26: 9400 | AZ26: Synthetic Sample
A27: CAR-1026 | B27: Mahindra | C27: Mahindra BE 6 | D27: BE 6 | E27: Pack Three 79 kWh | F27: 2024 | G27: 2025 | H27: Used | I27: Coupe | J27: Electric | K27: Automatic | L27: 1 | M27: 2095000 | N27: 2555000 | O27: Yes | P27: 1990000 | Q27: 525000 | R27: =IF(V27="No",0,MAX(0,M27-Q27)) -> 1570000 | S27: 10.55 | T27: 48 | U27: =IF(OR(R27<=0,S27<0,T27<=0),"",IF(S27=0,R27/T27,-PMT(S27/1200,T27,R27))) -> 40235 | V27: Yes | X27: 282 | Z27: 682 | AA27: 79 | AB27: 5 | AC27: 5 | AD27: 455 | AE27: 5 Star (Bharat NCAP) | AF27: 7 | AG27: Yes | AH27: Yes | AI27: Yes | AJ27: Titan Grey | AK27: Like New | AL27: 22200 | AM27: 2026-12-18 | AN27: Maharashtra | AO27: Pune | AP27: Available | AQ27: 2026-09-10 | AR27: Dealer | AS27: Yes | AT27: Yes | AU27: No | AV27: INGLO Born Electric Platform, Infinity Roof, 16-Speaker Harman Kardon Dolby Atmos, AR HUD | AW27: Well-maintained 2024 like new condition Mahindra BE 6 Pack Three 79 kWh (Automatic) in Pune. Powered by a 79 kWh battery delivering 682 km certified range. Complete service history available. | AX27: Enthusiast | AY27: 6300 | AZ27: Synthetic Sample
A28: CAR-1027 | B28: Honda | C28: Honda City | D28: City | E28: ZX 1.5L i-VTEC CVT | F28: 2020 | G28: 2020 | H28: Used | I28: Sedan | J28: Petrol | K28: CVT | L28: 1 | M28: 765000 | N28: 1390000 | O28: Yes | P28: 735000 | Q28: 190000 | R28: =IF(V28="No",0,MAX(0,M28-Q28)) -> 575000 | S28: 11.15 | T28: 60 | U28: =IF(OR(R28<=0,S28<0,T28<=0),"",IF(S28=0,R28/T28,-PMT(S28/1200,T28,R28))) -> 12545 | V28: Yes | W28: 1498 | X28: 119 | Y28: 18.4 | AB28: 5 | AC28: 4 | AD28: 506 | AE28: 5 Star (ASEAN NCAP) | AF28: 6 | AG28: Yes | AH28: Yes | AI28: Yes | AJ28: Abyss Black | AK28: Excellent | AL28: 57400 | AM28: 2027-03-23 | AN28: Tamil Nadu | AO28: Coimbatore | AP28: Available | AQ28: 2026-10-13 | AR28: Dealer | AS28: Yes | AT28: No | AU28: No | AV28: Honda Sensing ADAS, LaneWatch Camera, Electric Sunroof, Walk Away Auto Lock | AW28: Well-maintained 2020 excellent condition Honda City ZX 1.5L i-VTEC CVT (CVT) in Coimbatore. Powered by a 1498 cc petrol engine delivering 18.4 km/l. Complete service history available. | AX28: Family | AY28: 10500 | AZ28: Synthetic Sample
A29: CAR-1028 | B29: Honda | C29: Honda City e:HEV | D29: City e:HEV | E29: ZX 1.5L Atkinson e-CVT | F29: 2015 | G29: 2015 | H29: Used | I29: Sedan | J29: Hybrid | K29: CVT | L29: 2 | M29: 450000 | N29: 1490000 | O29: No | P29: 450000 | Q29: 115000 | R29: =IF(V29="No",0,MAX(0,M29-Q29)) -> 0 | S29: 0 | T29: 0 | U29: =IF(OR(R29<=0,S29<0,T29<=0),"",IF(S29=0,R29/T29,-PMT(S29/1200,T29,R29))) | V29: No | W29: 1498 | X29: 124 | Y29: 27.13 | AB29: 5 | AC29: 4 | AD29: 410 | AE29: 5 Star (ASEAN NCAP) | AF29: 6 | AG29: Yes | AH29: Yes | AI29: Yes | AJ29: Starry Night Blue | AK29: Fair | AL29: 122400 | AM29: 2026-12-01 | AN29: Kerala | AO29: Kochi | AP29: Available | AQ29: 2026-09-16 | AR29: Individual | AS29: Yes | AT29: No | AU29: No | AV29: Self-Charging Strong Two-Motor Hybrid, Honda Sensing ADAS, Electronic Parking Brake | AW29: Well-maintained 2015 fair condition Honda City e:HEV ZX 1.5L Atkinson e-CVT (CVT) in Kochi. Powered by a 1498 cc hybrid engine delivering 27.13 km/l. Complete service history available. | AX29: Business | AY29: 13100 | AZ29: Synthetic Sample
A30: CAR-1029 | B30: Honda | C30: Honda Elevate | D30: Elevate | E30: ZX 1.5L i-VTEC CVT | F30: 2023 | G30: 2023 | H30: Used | I30: SUV | J30: Petrol | K30: CVT | L30: 1 | M30: 1125000 | N30: 1520000 | O30: Yes | P30: 1070000 | Q30: 280000 | R30: =IF(V30="No",0,MAX(0,M30-Q30)) -> 845000 | S30: 10.7 | T30: 48 | U30: =IF(OR(R30<=0,S30<0,T30<=0),"",IF(S30=0,R30/T30,-PMT(S30/1200,T30,R30))) -> 21717 | V30: Yes | W30: 1498 | X30: 119 | Y30: 16.92 | AB30: 5 | AC30: 5 | AD30: 458 | AF30: 6 | AG30: Yes | AH30: Yes | AI30: Yes | AJ30: Pearl Arctic White | AK30: Like New | AL30: 24200 | AM30: 2027-05-06 | AN30: Gujarat | AO30: Ahmedabad | AP30: Reserved | AQ30: 2026-10-19 | AR30: Dealer | AS30: No | AT30: Yes | AU30: No | AV30: 220mm Ground Clearance, Honda Sensing ADAS, 10.25-inch IPS HD Touchscreen, Sunroof | AW30: Well-maintained 2023 like new condition Honda Elevate ZX 1.5L i-VTEC CVT (CVT) in Ahmedabad. Powered by a 1498 cc petrol engine delivering 16.92 km/l. Inspected for mechanical reliability. | AX30: Family | AY30: 9600 | AZ30: Synthetic Sample
A31: CAR-1030 | B31: Honda | C31: Honda Amaze | D31: Amaze | E31: ZX 1.2L i-VTEC CVT | F31: 2017 | G31: 2017 | H31: Used | I31: Sedan | J31: Petrol | K31: CVT | L31: 2 | M31: 315000 | N31: 845000 | O31: Yes | P31: 300000 | Q31: 80000 | R31: =IF(V31="No",0,MAX(0,M31-Q31)) -> 235000 | S31: 11.6 | T31: 60 | U31: =IF(OR(R31<=0,S31<0,T31<=0),"",IF(S31=0,R31/T31,-PMT(S31/1200,T31,R31))) -> 5180 | V31: Yes | W31: 1199 | X31: 89 | Y31: 19.46 | AB31: 5 | AC31: 4 | AD31: 416 | AF31: 6 | AG31: Yes | AH31: Yes | AI31: Yes | AJ31: Titan Grey | AK31: Good | AL31: 87900 | AM31: 2026-12-11 | AN31: West Bengal | AO31: Kolkata | AP31: Sold | AQ31: 2026-09-22 | AR31: Dealer | AS31: Yes | AT31: No | AU31: No | AV31: Honda Sensing ADAS, LaneWatch Camera, Wireless Charger, Paddle Shifters | AW31: Well-maintained 2017 good condition Honda Amaze ZX 1.2L i-VTEC CVT (CVT) in Kolkata. Powered by a 1199 cc petrol engine delivering 19.46 km/l. Complete service history available. | AX31: First-Time Buyer | AY31: 9700 | AZ31: Synthetic Sample
A32: CAR-1031 | B32: Toyota | C32: Toyota Innova Hycross | D32: Innova Hycross | E32: ZX (O) 2.0L Strong Hybrid e-Drive | F32: 2025 | G32: 2026 | H32: Used | I32: MUV | J32: Hybrid | K32: CVT | L32: 1 | M32: 2735000 | N32: 3020000 | O32: No | P32: 2735000 | Q32: 685000 | R32: =IF(V32="No",0,MAX(0,M32-Q32)) -> 2050000 | S32: 10.4 | T32: 36 | U32: =IF(OR(R32<=0,S32<0,T32<=0),"",IF(S32=0,R32/T32,-PMT(S32/1200,T32,R32))) -> 66533 | V32: Yes | W32: 1987 | X32: 184 | Y32: 23.24 | AB32: 7 | AC32: 5 | AD32: 300 | AE32: 5 Star (Bharat NCAP) | AF32: 6 | AG32: Yes | AH32: Yes | AI32: Yes | AJ32: Abyss Black | AK32: Like New | AL32: 8100 | AM32: 2027-07-16 | AN32: Tamil Nadu | AO32: Chennai | AP32: Available | AQ32: 2026-10-03 | AR32: Individual | AS32: Yes | AT32: Yes | AU32: Unknown | AV32: Powered Ottoman 2nd Row Seats, Toyota Safety Sense ADAS, Panoramic Sunroof, JBL Audio | AW32: Well-maintained 2025 like new condition Toyota Innova Hycross ZX (O) 2.0L Strong Hybrid e-Drive (CVT) in Chennai. Powered by a 1987 cc hybrid engine delivering 23.24 km/l. Complete service history available. | AX32: Family | AY32: 10600 | AZ32: Synthetic Sample
A33: CAR-1032 | B33: Toyota | C33: Toyota Fortuner | D33: Fortuner | E33: Legender 2.8L 4x4 AT | F33: 2019 | G33: 2019 | H33: Used | I33: SUV | J33: Diesel | K33: Automatic | L33: 1 | M33: 1780000 | N33: 3930000 | O33: Yes | P33: 1690000 | Q33: 445000 | R33: =IF(V33="No",0,MAX(0,M33-Q33)) -> 1335000 | S33: 11.3 | T33: 48 | U33: =IF(OR(R33<=0,S33<0,T33<=0),"",IF(S33=0,R33/T33,-PMT(S33/1200,T33,R33))) -> 34699 | V33: Yes | W33: 2755 | X33: 201 | Y33: 14.2 | AB33: 7 | AC33: 5 | AD33: 296 | AE33: 5 Star (ASEAN NCAP) | AF33: 7 | AG33: Yes | AH33: Yes | AI33: Yes | AJ33: Starry Night Blue | AK33: Fair | AL33: 97000 | AM33: 2026-12-21 | AN33: Karnataka | AO33: Bengaluru | AP33: Available | AQ33: 2026-09-06 | AR33: Dealer | AS33: Yes | AT33: No | AU33: No | AV33: Quad-LED Headlamps, Active Traction Control (A-TRC), Kick-Sensor Powered Tailgate, JBL 11-Speaker | AW33: Well-maintained 2019 fair condition Toyota Fortuner Legender 2.8L 4x4 AT (Automatic) in Bengaluru. Powered by a 2755 cc diesel engine delivering 14.2 km/l. Complete service history available. | AX33: Business | AY33: 18600 | AZ33: Synthetic Sample
A34: CAR-1033 | B34: Toyota | C34: Toyota Urban Cruiser Hyryder | D34: Urban Cruiser Hyryder | E34: V 1.5L e-Drive Hybrid | F34: 2023 | G34: 2023 | H34: Used | I34: SUV | J34: Hybrid | K34: CVT | L34: 1 | M34: 1385000 | N34: 1870000 | O34: Yes | P34: 1330000 | Q34: 345000 | R34: =IF(V34="No",0,MAX(0,M34-Q34)) -> 1040000 | S34: 10.7 | T34: 60 | U34: =IF(OR(R34<=0,S34<0,T34<=0),"",IF(S34=0,R34/T34,-PMT(S34/1200,T34,R34))) -> 22457 | V34: Yes | W34: 1490 | X34: 114 | Y34: 27.97 | AB34: 5 | AC34: 5 | AD34: 265 | AF34: 6 | AG34: Yes | AH34: Yes | AI34: Yes | AJ34: Pearl Arctic White | AK34: Like New | AL34: 27600 | AM34: 2027-09-26 | AN34: Telangana | AO34: Hyderabad | AP34: Available | AQ34: 2026-10-09 | AR34: Dealer | AS34: Yes | AT34: Yes | AU34: No | AV34: Self-Charging Strong Hybrid, Panoramic Sunroof, Head-Up Display, Ventilated Leather Seats | AW34: Well-maintained 2023 like new condition Toyota Urban Cruiser Hyryder V 1.5L e-Drive Hybrid (CVT) in Hyderabad. Powered by a 1490 cc hybrid engine delivering 27.97 km/l. Complete service history available. | AX34: Family | AY34: 10000 | AZ34: Synthetic Sample
A35: CAR-1034 | B35: Toyota | C35: Toyota Glanza | D35: Glanza | E35: V 1.2L DualJet AMT | F35: 2021 | G35: 2021 | H35: Used | I35: Hatchback | J35: Petrol | K35: AMT | L35: 2 | M35: 530000 | N35: 875000 | O35: No | P35: 530000 | Q35: 135000 | R35: =IF(V35="No",0,MAX(0,M35-Q35)) -> 395000 | S35: 11 | T35: 36 | U35: =IF(OR(R35<=0,S35<0,T35<=0),"",IF(S35=0,R35/T35,-PMT(S35/1200,T35,R35))) -> 12932 | V35: Yes | W35: 1197 | X35: 89 | Y35: 22.94 | AB35: 5 | AC35: 5 | AD35: 318 | AF35: 6 | AG35: Yes | AH35: Yes | AI35: Yes | AJ35: Titan Grey | AK35: Excellent | AL35: 45500 | AM35: 2026-12-04 | AN35: Maharashtra | AO35: Mumbai | AP35: Available | AQ35: 2026-09-12 | AR35: Individual | AS35: Yes | AT35: No | AU35: No | AV35: 360 Degree Camera, HUD, 9-inch Smart Playcast, Toyota i-Connect | AW35: Well-maintained 2021 excellent condition Toyota Glanza V 1.2L DualJet AMT (AMT) in Mumbai. Powered by a 1197 cc petrol engine delivering 22.94 km/l. Complete service history available. | AX35: Daily Commuter | AY35: 7800 | AZ35: Synthetic Sample
A36: CAR-1035 | B36: Kia | C36: Kia Seltos | D36: Seltos | E36: GTX+ 1.5L Turbo GDi DCT | F36: 2016 | G36: 2016 | H36: Used | I36: SUV | J36: Petrol | K36: DCT | L36: 2 | M36: 510000 | N36: 1525000 | O36: Yes | P36: 485000 | Q36: 130000 | R36: =IF(V36="No",0,MAX(0,M36-Q36)) -> 380000 | S36: 11.75 | T36: 48 | U36: =IF(OR(R36<=0,S36<0,T36<=0),"",IF(S36=0,R36/T36,-PMT(S36/1200,T36,R36))) -> 9960 | V36: Yes | W36: 1482 | X36: 158 | Y36: 17.9 | AB36: 5 | AC36: 5 | AD36: 433 | AF36: 6 | AG36: Yes | AH36: Yes | AI36: Yes | AJ36: Abyss Black | AK36: Fair | AL36: 95600 | AM36: 2027-11-09 | AN36: Delhi | AO36: Delhi | AP36: Reserved | AQ36: 2026-10-15 | AR36: Dealer | AS36: Yes | AT36: No | AU36: No | AV36: ADAS Level 2 (19 Autonomous Features), Dual Pane Panoramic Sunroof, Bose 8-Speaker Audio | AW36: Well-maintained 2016 fair condition Kia Seltos GTX+ 1.5L Turbo GDi DCT (DCT) in Delhi. Powered by a 1482 cc petrol engine delivering 17.9 km/l. Complete service history available. | AX36: Family | AY36: 13900 | AZ36: Synthetic Sample
A37: CAR-1036 | B37: Kia | C37: Kia Sonet | D37: Sonet | E37: GTX+ 1.5L CRDi AT | F37: 2023 | G37: 2024 | H37: Used | I37: SUV | J37: Diesel | K37: Automatic | L37: 1 | M37: 1070000 | N37: 1445000 | O37: Yes | P37: 1025000 | Q37: 270000 | R37: =IF(V37="No",0,MAX(0,M37-Q37)) -> 800000 | S37: 10.7 | T37: 60 | U37: =IF(OR(R37<=0,S37<0,T37<=0),"",IF(S37=0,R37/T37,-PMT(S37/1200,T37,R37))) -> 17274 | V37: Yes | W37: 1493 | X37: 114 | Y37: 18.6 | AB37: 5 | AC37: 5 | AD37: 385 | AF37: 6 | AG37: Yes | AH37: Yes | AI37: Yes | AJ37: Starry Night Blue | AK37: Excellent | AL37: 36700 | AM37: 2026-12-14 | AN37: Maharashtra | AO37: Pune | AP37: Sold | AQ37: 2026-09-18 | AR37: Dealer | AS37: No | AT37: Yes | AU37: No | AV37: Level 1 ADAS, 360 Surround View Monitor, Ventilated Front Seats, Bose 7-Speaker System | AW37: Well-maintained 2023 excellent condition Kia Sonet GTX+ 1.5L CRDi AT (Automatic) in Pune. Powered by a 1493 cc diesel engine delivering 18.6 km/l. Inspected for mechanical reliability. | AX37: Daily Commuter | AY37: 9700 | AZ37: Synthetic Sample
A38: CAR-1037 | B38: Kia | C38: Kia Carens | D38: Carens | E38: Luxury Plus 1.5L Turbo DCT 7S | F38: 2018 | G38: 2018 | H38: Used | I38: MUV | J38: Petrol | K38: DCT | L38: 3 | M38: 635000 | N38: 1555000 | O38: No | P38: 635000 | Q38: 160000 | R38: =IF(V38="No",0,MAX(0,M38-Q38)) -> 475000 | S38: 11.45 | T38: 36 | U38: =IF(OR(R38<=0,S38<0,T38<=0),"",IF(S38=0,R38/T38,-PMT(S38/1200,T38,R38))) -> 15652 | V38: Yes | W38: 1482 | X38: 158 | Y38: 16.8 | AB38: 7 | AC38: 5 | AD38: 216 | AE38: 3 Star (Global NCAP) | AF38: 6 | AG38: Yes | AH38: Yes | AI38: Yes | AJ38: Pearl Arctic White | AK38: Fair | AL38: 95500 | AM38: 2027-01-19 | AN38: Tamil Nadu | AO38: Coimbatore | AP38: Available | AQ38: 2026-10-21 | AR38: Individual | AS38: Yes | AT38: No | AU38: No | AV38: One-Touch Easy Electric Tumble 2nd Row, SkyLight Sunroof, Ventilated Front Seats, 64-Colour Ambient Light | AW38: Well-maintained 2018 fair condition Kia Carens Luxury Plus 1.5L Turbo DCT 7S (DCT) in Coimbatore. Powered by a 1482 cc petrol engine delivering 16.8 km/l. Complete service history available. | AX38: Family | AY38: 12500 | AZ38: Synthetic Sample
A39: CAR-1038 | B39: Kia | C39: Kia EV6 | D39: EV6 | E39: GT Line AWD 77.4 kWh | F39: 2024 | G39: 2024 | H39: Used | I39: SUV | J39: Electric | K39: Automatic | L39: 1 | M39: 5130000 | N39: 6265000 | O39: Yes | P39: 4875000 | Q39: 1285000 | R39: =IF(V39="No",0,MAX(0,M39-Q39)) -> 3845000 | S39: 10.55 | T39: 48 | U39: =IF(OR(R39<=0,S39<0,T39<=0),"",IF(S39=0,R39/T39,-PMT(S39/1200,T39,R39))) -> 98538 | V39: Yes | X39: 321 | Z39: 708 | AA39: 77.4 | AB39: 5 | AC39: 5 | AD39: 490 | AE39: 5 Star (Euro NCAP) | AF39: 8 | AG39: Yes | AH39: Yes | AI39: Yes | AJ39: Titan Grey | AK39: Like New | AL39: 23500 | AM39: 2026-12-24 | AN39: Kerala | AO39: Kochi | AP39: Available | AQ39: 2026-09-02 | AR39: Dealer | AS39: Yes | AT39: Yes | AU39: No | AV39: Dual Motor All-Wheel Drive, 0-100 km/h in 5.2s, AR Head-Up Display, Meridian 14-Speaker Audio | AW39: Well-maintained 2024 like new condition Kia EV6 GT Line AWD 77.4 kWh (Automatic) in Kochi. Powered by a 77.4 kWh battery delivering 708 km certified range. Complete service history available. | AX39: Enthusiast | AY39: 7800 | AZ39: Synthetic Sample
A40: CAR-1039 | B40: Renault | C40: Renault Kiger | D40: Kiger | E40: RXZ 1.0L Turbo X-Tronic CVT | F40: 2020 | G40: 2020 | H40: Used | I40: SUV | J40: Petrol | K40: CVT | L40: 1 | M40: 525000 | N40: 955000 | O40: Yes | P40: 505000 | Q40: 130000 | R40: =IF(V40="No",0,MAX(0,M40-Q40)) -> 395000 | S40: 11.15 | T40: 60 | U40: =IF(OR(R40<=0,S40<0,T40<=0),"",IF(S40=0,R40/T40,-PMT(S40/1200,T40,R40))) -> 8618 | V40: Yes | W40: 999 | X40: 99 | Y40: 18.24 | AB40: 5 | AC40: 5 | AD40: 405 | AE40: 4 Star (Global NCAP) | AF40: 4 | AG40: Yes | AH40: Yes | AI40: Yes | AJ40: Abyss Black | AK40: Good | AL40: 71300 | AM40: 2027-03-02 | AN40: Gujarat | AO40: Ahmedabad | AP40: Available | AQ40: 2026-10-05 | AR40: Dealer | AS40: Yes | AT40: No | AU40: No | AV40: Multi-Sense Drive Modes, 3D Arkamys Sound System, Wireless Smartphone Replication, PM2.5 Filter | AW40: Well-maintained 2020 good condition Renault Kiger RXZ 1.0L Turbo X-Tronic CVT (CVT) in Ahmedabad. Powered by a 999 cc petrol engine delivering 18.24 km/l. Complete service history available. | AX40: First-Time Buyer | AY40: 8900 | AZ40: Synthetic Sample
...

Sheet Brand Summary
A1: INDIAN CAR MARKETPLACE — BRAND-LEVEL SUMMARY REPORT
A2: Note: All summary statistics dynamically calculate from the 'Car Listings' worksheet (rows 2 to 161). All monetary values in INR (₹).
A4: Brand | B4: Number of Listings | C4: Average Selling Price (INR) | D4: Minimum Price (INR) | E4: Maximum Price (INR)
A5: Audi | B5: =COUNTIF('Car Listings'!$B$2:$B$161, A5) -> 6 | C5: =AVERAGEIF('Car Listings'!$B$2:$B$161, A5, 'Car Listings'!$M$2:$M$161) -> 4661667 | D5: =SUMPRODUCT(MIN(('Car Listings'!$B$2:$B$161=A5)*('Car Listings'!$M$2:$M$161)+('Car Listings'!$B$2:$B$161<>A5)*1000000000)) -> 1040000 | E5: =SUMPRODUCT(MAX(('Car Listings'!$B$2:$B$161=A5)*('Car Listings'!$M$2:$M$161))) -> 12700000
A6: BMW | B6: =COUNTIF('Car Listings'!$B$2:$B$161, A6) -> 6 | C6: =AVERAGEIF('Car Listings'!$B$2:$B$161, A6, 'Car Listings'!$M$2:$M$161) -> 3058333 | D6: =SUMPRODUCT(MIN(('Car Listings'!$B$2:$B$161=A6)*('Car Listings'!$M$2:$M$161)+('Car Listings'!$B$2:$B$161<>A6)*1000000000)) -> 1065000 | E6: =SUMPRODUCT(MAX(('Car Listings'!$B$2:$B$161=A6)*('Car Listings'!$M$2:$M$161))) -> 5645000
A7: BYD | B7: =COUNTIF('Car Listings'!$B$2:$B$161, A7) -> 4 | C7: =AVERAGEIF('Car Listings'!$B$2:$B$161, A7, 'Car Listings'!$M$2:$M$161) -> 3555000 | D7: =SUMPRODUCT(MIN(('Car Listings'!$B$2:$B$161=A7)*('Car Listings'!$M$2:$M$161)+('Car Listings'!$B$2:$B$161<>A7)*1000000000)) -> 2645000 | E7: =SUMPRODUCT(MAX(('Car Listings'!$B$2:$B$161=A7)*('Car Listings'!$M$2:$M$161))) -> 4555000
A8: Honda | B8: =COUNTIF('Car Listings'!$B$2:$B$161, A8) -> 12 | C8: =AVERAGEIF('Car Listings'!$B$2:$B$161, A8, 'Car Listings'!$M$2:$M$161) -> 821250 | D8: =SUMPRODUCT(MIN(('Car Listings'!$B$2:$B$161=A8)*('Car Listings'!$M$2:$M$161)+('Car Listings'!$B$2:$B$161<>A8)*1000000000)) -> 315000 | E8: =SUMPRODUCT(MAX(('Car Listings'!$B$2:$B$161=A8)*('Car Listings'!$M$2:$M$161))) -> 1450000
A9: Hyundai | B9: =COUNTIF('Car Listings'!$B$2:$B$161, A9) -> 21 | C9: =AVERAGEIF('Car Listings'!$B$2:$B$161, A9, 'Car Listings'!$M$2:$M$161) -> 1233571 | D9: =SUMPRODUCT(MIN(('Car Listings'!$B$2:$B$161=A9)*('Car Listings'!$M$2:$M$161)+('Car Listings'!$B$2:$B$161<>A9)*1000000000)) -> 180000 | E9: =SUMPRODUCT(MAX(('Car Listings'!$B$2:$B$161=A9)*('Car Listings'!$M$2:$M$161))) -> 4065000
A10: Jeep | B10: =COUNTIF('Car Listings'!$B$2:$B$161, A10) -> 2 | C10: =AVERAGEIF('Car Listings'!$B$2:$B$161, A10, 'Car Listings'!$M$2:$M$161) -> 1962500 | D10: =SUMPRODUCT(MIN(('Car Listings'!$B$2:$B$161=A10)*('Car Listings'!$M$2:$M$161)+('Car Listings'!$B$2:$B$161<>A10)*1000000000)) -> 1065000 | E10: =SUMPRODUCT(MAX(('Car Listings'!$B$2:$B$161=A10)*('Car Listings'!$M$2:$M$161))) -> 2860000
A11: Kia | B11: =COUNTIF('Car Listings'!$B$2:$B$161, A11) -> 12 | C11: =AVERAGEIF('Car Listings'!$B$2:$B$161, A11, 'Car Listings'!$M$2:$M$161) -> 2194167 | D11: =SUMPRODUCT(MIN(('Car Listings'!$B$2:$B$161=A11)*('Car Listings'!$M$2:$M$161)+('Car Listings'!$B$2:$B$161<>A11)*1000000000)) -> 510000 | E11: =SUMPRODUCT(MAX(('Car Listings'!$B$2:$B$161=A11)*('Car Listings'!$M$2:$M$161))) -> 6595000
A12: MG | B12: =COUNTIF('Car Listings'!$B$2:$B$161, A12) -> 6 | C12: =AVERAGEIF('Car Listings'!$B$2:$B$161, A12, 'Car Listings'!$M$2:$M$161) -> 1255000 | D12: =SUMPRODUCT(MIN(('Car Listings'!$B$2:$B$161=A12)*('Car Listings'!$M$2:$M$161)+('Car Listings'!$B$2:$B$161<>A12)*1000000000)) -> 545000 | E12: =SUMPRODUCT(MAX(('Car Listings'!$B$2:$B$161=A12)*('Car Listings'!$M$2:$M$161))) -> 1550000
A13: Mahindra | B13: =COUNTIF('Car Listings'!$B$2:$B$161, A13) -> 15 | C13: =AVERAGEIF('Car Listings'!$B$2:$B$161, A13, 'Car Listings'!$M$2:$M$161) -> 1545600 | D13: =SUMPRODUCT(MIN(('Car Listings'!$B$2:$B$161=A13)*('Car Listings'!$M$2:$M$161)+('Car Listings'!$B$2:$B$161<>A13)*1000000000)) -> 615000 | E13: =SUMPRODUCT(MAX(('Car Listings'!$B$2:$B$161=A13)*('Car Listings'!$M$2:$M$161))) -> 2690000
A14: Maruti Suzuki | B14: =COUNTIF('Car Listings'!$B$2:$B$161, A14) -> 21 | C14: =AVERAGEIF('Car Listings'!$B$2:$B$161, A14, 'Car Listings'!$M$2:$M$161) -> 721571 | D14: =SUMPRODUCT(MIN(('Car Listings'!$B$2:$B$161=A14)*('Car Listings'!$M$2:$M$161)+('Car Listings'!$B$2:$B$161<>A14)*1000000000)) -> 150000 | E14: =SUMPRODUCT(MAX(('Car Listings'!$B$2:$B$161=A14)*('Car Listings'!$M$2:$M$161))) -> 1999000
A15: Mercedes-Benz | B15: =COUNTIF('Car Listings'!$B$2:$B$161, A15) -> 6 | C15: =AVERAGEIF('Car Listings'!$B$2:$B$161, A15, 'Car Listings'!$M$2:$M$161) -> 4096667 | D15: =SUMPRODUCT(MIN(('Car Listings'!$B$2:$B$161=A15)*('Car Listings'!$M$2:$M$161)+('Car Listings'!$B$2:$B$161<>A15)*1000000000)) -> 1685000 | E15: =SUMPRODUCT(MAX(('Car Listings'!$B$2:$B$161=A15)*('Car Listings'!$M$2:$M$161))) -> 7590000
A16: Renault | B16: =COUNTIF('Car Listings'!$B$2:$B$161, A16) -> 6 | C16: =AVERAGEIF('Car Listings'!$B$2:$B$161, A16, 'Car Listings'!$M$2:$M$161) -> 346667 | D16: =SUMPRODUCT(MIN(('Car Listings'!$B$2:$B$161=A16)*('Car Listings'!$M$2:$M$161)+('Car Listings'!$B$2:$B$161<>A16)*1000000000)) -> 185000 | E16: =SUMPRODUCT(MAX(('Car Listings'!$B$2:$B$161=A16)*('Car Listings'!$M$2:$M$161))) -> 540000
... A20: Volkswagen | B20: =COUNTIF('Car Listings'!$B$2:$B$161, A20) -> 4 | C20: =AVERAGEIF('Car Listings'!$B$2:$B$161, A20, 'Car Listings'!$M$2:$M$161) -> 1117500 | D20: =SUMPRODUCT(MIN(('Car Listings'!$B$2:$B$161=A20)*('Car Listings'!$M$2:$M$161)+('Car Listings'!$B$2:$B$161<>A20)*1000000000)) -> 615000 | E20: =SUMPRODUCT(MAX(('Car Listings'!$B$2:$B$161=A20)*('Car Listings'!$M$2:$M$161))) -> 1535000
A21: Total / Overall Market | B21: =SUM(B5:B20) -> 160 | C21: =AVERAGE('Car Listings'!$M$2:$M$161) -> 1643119 | D21: =MIN('Car Listings'!$M$2:$M$161) -> 150000 | E21: =MAX('Car Listings'!$M$2:$M$161) -> 12700000

Sheet Data Dictionary
A1: DATA DICTIONARY & SYNTHETIC DATA DOCUMENTATION
A2: Limitations of Synthetic Data: Vehicle technical specs and safety ratings reflect verified manufacturer/NCAP reference data. Listing IDs, prices, odometer readings, and availability are synthetic samples for AI assistant testing. Interest rates and EMIs are illustrative estimates, not binding lender offers.
A3: Excel Col | B3: Column Name | C3: Section / Category | D3: Data Type | E3: Units / Format | F3: Data Nature | G3: Description & Formula / Validation Rule | H3: Example Value
A4: A | B4: Listing ID | C4: Basic Information | D4: String | E4: Alphanumeric ID | F4: Synthetic Sample | G4: Unique primary key identifier for each vehicle listing (CAR-1001 to CAR-1160). | H4: CAR-1001
A5: B | B5: Brand | C5: Basic Information | D5: String | E5: Text | F5: Verified Spec | G5: Automobile manufacturer / OEM brand name in the Indian market. | H5: Maruti Suzuki
A6: C | B6: Car Name | C6: Basic Information | D6: String | E6: Text | F6: Verified Spec | G6: Full commercial vehicle name combining Brand and Model. | H6: Maruti Suzuki Swift
A7: D | B7: Model | C7: Basic Information | D7: String | E7: Text | F7: Verified Spec | G7: Specific vehicle model line. | H7: Swift
A8: E | B8: Variant | C8: Basic Information | D8: String | E8: Text | F8: Verified Spec | G8: Manufacturer trim level and powertrain badge. | H8: ZXi+ 1.2L DualJet
A9: F | B9: Manufacturing Year | C9: Basic Information | D9: Integer | E9: Year (YYYY) | F9: Synthetic Sample | G9: Year the vehicle was manufactured (2015–2026). | H9: 2024
A10: G | B10: Registration Year | C10: Basic Information | D10: Integer | E10: Year (YYYY) | F10: Synthetic Sample | G10: Year the vehicle was registered with the RTO (>= Manufacturing Year). | H10: 2024
A11: H | B11: New or Used | C11: Basic Information | D11: Categorical | E11: Dropdown | F11: Synthetic Sample | G11: Indicates whether the vehicle is a brand-new showroom unit or pre-owned. | H11: Used
A12: I | B12: Vehicle Type | C12: Basic Information | D12: Categorical | E12: Dropdown | F12: Verified Spec | G12: Body style classification (Hatchback, Sedan, SUV, MUV, Luxury, Coupe). | H12: SUV
A13: J | B13: Fuel Type | C13: Basic Information | D13: Categorical | E13: Dropdown | F13: Verified Spec | G13: Primary propulsion fuel/energy type (Petrol, Diesel, Electric, CNG, Hybrid). | H13: Petrol
A14: K | B14: Transmission | C14: Basic Information | D14: Categorical | E14: Dropdown | F14: Verified Spec | G14: Gearbox type (Manual, Automatic, AMT, CVT, DCT). | H14: DCT
... A55: AZ | B55: Source Type | C55: Additional Information | D55: Categorical | E55: Verified Source / Synthetic Sample | F55: Metadata | G55: Explicitly labels whether the listing row is a live verified listing or a synthetic sample. | H55: Synthetic Sample
A56: BA | B56: Source URL | C56: Additional Information | D56: String (Nullable) | E56: URL | F56: Metadata | G56: Left intentionally blank for Synthetic Sample rows to avoid inventing live URLs.

Sheet EMI Calculator
A1: INTERACTIVE AUTOMOBILE LOAN & EMI CALCULATOR (REDUCING-BALANCE FORMULA)
A2: Disclaimer: Interest rates and monthly EMI values are illustrative estimates for AI assistant simulation and financial planning, not binding lender offers.
A4: Parameter / Metric | B4: Input / Calculated Value | C4: Unit & Formula Explanation | D4: Notes
A5: Vehicle Selling Price (INR) | B5: 1250000 | C5: INR (User Editable Input) | D5: Change this value to test
A6: Down Payment (INR) | B6: 250000 | C6: INR (User Editable Input) | D6: Upfront margin paid by buyer
A7: Principal Loan Amount (INR) | B7: =MAX(0,B5-B6) -> 1000000 | C7: Formula: =MAX(0, B5-B6) | D7: Automatically updates
A8: Annual Interest Rate (% per annum) | B8: 9.25 | C8: % per annum (User Editable Input) | D8: Set to 0 to verify zero-interest loan
A9: EMI Tenure (Months) | B9: 60 | C9: Months (User Editable Input) | D9: Standard tenures: 12 to 84 months
A10: Estimated Monthly EMI (INR) | B10: =IF(OR(B7<=0,B8<0,B9<=0),"",IF(B8=0,B7/B9,-PMT(B8/1200,B9,B7))) -> 20880 | C10: Formula: =IF(OR(B7<=0,B8<0,B9<=0),"",IF(B8=0,B7/B9,-PMT(B8/1200,B9,B7))) | D10: Illustrative Monthly Installment
A11: Total Amount Payable on Loan (INR) | B11: =IF(B10="","",B10*B9) -> 1252792 | C11: Formula: =IF(B10="","",B10*B9) | D11: Principal + Total Interest
A12: Total Interest Payable (INR) | B12: =IF(B11="","",MAX(0,B11-B7)) -> 252792 | C12: Formula: =IF(B11="","",MAX(0,B11-B7)) | D12: Total cost of borrowing
A13: Total On-Road Outflow incl. Down Payment (INR) | B13: =IF(B11="","",B6+B11) -> 1502792 | C13: Formula: =IF(B11="","",B6+B11) | D13: Down Payment + Total EMIs
A15: Tenure Sensitivity Comparison (Months) | B15: Estimated Monthly EMI (INR) | C15: Total Interest Payable (INR) | D15: Total Loan Repayment (INR)
A16: 12 | B16: =IF(OR($B$7<=0,$B$8<0,A16<=0),"",IF($B$8=0,$B$7/A16,-PMT($B$8/1200,A16,$B$7))) -> 87567 | C16: =IF(B16="","",(B16*A16)-$B$7) -> 50804 | D16: =IF(B16="","",B16*A16) -> 1050804
A17: 24 | B17: =IF(OR($B$7<=0,$B$8<0,A17<=0),"",IF($B$8=0,$B$7/A17,-PMT($B$8/1200,A17,$B$7))) -> 45800 | C17: =IF(B17="","",(B17*A17)-$B$7) -> 99200 | D17: =IF(B17="","",B17*A17) -> 1099200
A18: 36 | B18: =IF(OR($B$7<=0,$B$8<0,A18<=0),"",IF($B$8=0,$B$7/A18,-PMT($B$8/1200,A18,$B$7))) -> 31916 | C18: =IF(B18="","",(B18*A18)-$B$7) -> 148976 | D18: =IF(B18="","",B18*A18) -> 1148976
A19: 48 | B19: =IF(OR($B$7<=0,$B$8<0,A19<=0),"",IF($B$8=0,$B$7/A19,-PMT($B$8/1200,A19,$B$7))) -> 25004 | C19: =IF(B19="","",(B19*A19)-$B$7) -> 200192 | D19: =IF(B19="","",B19*A19) -> 1200192
A20: 60 | B20: =IF(OR($B$7<=0,$B$8<0,A20<=0),"",IF($B$8=0,$B$7/A20,-PMT($B$8/1200,A20,$B$7))) -> 20880 | C20: =IF(B20="","",(B20*A20)-$B$7) -> 252800 | D20: =IF(B20="","",B20*A20) -> 1252800
A21: 72 | B21: =IF(OR($B$7<=0,$B$8<0,A21<=0),"",IF($B$8=0,$B$7/A21,-PMT($B$8/1200,A21,$B$7))) -> 18150 | C21: =IF(B21="","",(B21*A21)-$B$7) -> 306800 | D21: =IF(B21="","",B21*A21) -> 1306800
A22: 84 | B22: =IF(OR($B$7<=0,$B$8<0,A22<=0),"",IF($B$8=0,$B$7/A22,-PMT($B$8/1200,A22,$B$7))) -> 16216 | C22: =IF(B22="","",(B22*A22)-$B$7) -> 362144 | D22: =IF(B22="","",B22*A22) -> 1362144
